Workbook

Sheet Leyenda
A1: CÓMO USAR ESTE MODELO
A2: 1. Todo lo editable está en Parametros, en azul. Lo amarillo es SUPUESTO: reemplazalo por el dato real y el modelo entero se recalcula.
A3: 2. UE_Hoy y UE_Propuesta muestran cada vertical por transacción. La columna que importa es CONTRIBUCIÓN: lo que queda después del riel y los variables.
A4: 3. PyL_mensual aplica los volúmenes del mes 1 (azul) con la tasa de crecimiento. Los fijos cambian por fase (fila 4: 1 = F&F, 2 = Operación). El sueldo del founder va en B56/C56 de Parametros (0 = lo asume aparte). Prime y plan del prestador en filas 57–58.
A5: 4. Caja_retenciones muestra la plata que las tarjetas retienen y que vuelve meses después. No es pérdida: es capital de trabajo que hay que tener.
A7: LO QUE SE VERIFICÓ Y LO QUE NO
A8: Verificado en la calculadora de Nuvei: comisiones bancarias por tipo de tarjeta, tarifa Nuvei, 3DS, IVA sobre Nuvei, retención renta 2 %, retención IVA 30/70.
A9: Verificado en fuentes públicas: retención IVA 30 % bienes / 70 % servicios por emisoras de tarjeta; régimen de mercados en línea (Res. NAC-DGERCGC21-00000026); RIMPE sobre bruto; exclusión de comisionistas del RIMPE.
A10: SUPUESTO (amarillo): costo de DeUna y si retiene; mezcla de medios de pago; tickets; costos variables; costos fijos; % de prestadores que facturan con IVA; volúmenes.
A12: CONVENCIÓN DE COLORES: azul = input · negro = fórmula · verde = referencia a otra hoja · amarillo = supuesto a confirmar.

Sheet Parametros
A1: PARÁMETROS — Modelo económico e-PetPlace v1 · 10-sep-2026
A2: Azul = dato de entrada (editable). Negro = fórmula. Verde = viene de otra hoja. Amarillo = SUPUESTO que el founder debe confirmar o corregir.
A4: Riel de pago | B4: % banco (incl. IVA) | C4: % Nuvei (sin IVA) | D4: Fijo Nuvei $ (sin IVA) | E4: Costo total % (incl. IVA) | F4: Fijo total $ (incl. IVA) | G4: IVA recuperable % | H4: IVA recuperable fijo $ | I4: Retiene renta (1/0) | J4: Retiene IVA (1/0) | K4: Fuente
A5: Crédito corriente | B5: 0.0462 | C5: 0.015 | D5: 0.04 | E5: =B5+C5*(1+$B$21) -> 0.06345 | F5: =D5*(1+$B$21) -> 0.046 | G5: =B5*$B$21/(1+$B$21)+C5*$B$21 -> 0.008276087 | H5: =D5*$B$21 -> 0.006 | I5: 1 | J5: 1 | K5: Calculadora Nuvei — Costos del Servicio (hoja Corriente TC): 4,62% banco incl. IVA + 1,50% Nuvei + $0,04 3DS + IVA 15% sobre Nuvei
A6: Débito | B6: 0.023 | C6: 0.005 | D6: 0.04 | E6: =B6+C6*(1+$B$21) -> 0.02875 | F6: =D6*(1+$B$21) -> 0.046 | G6: =B6*$B$21/(1+$B$21)+C6*$B$21 -> 0.00375 | H6: =D6*$B$21 -> 0.006 | I6: 1 | J6: 1 | K6: Calculadora Nuvei (hoja Corriente TD): 2,30% + 0,50% + $0,04 + IVA
A7: DeUna (transferencia) | B7: 0 | C7: 0.02 | D7: 0 | E7: =B7+C7*(1+$B$21) -> 0.023 | F7: =D7*(1+$B$21) -> 0 | G7: =B7*$B$21/(1+$B$21)+C7*$B$21 -> 0.003 | H7: =D7*$B$21 -> 0 | I7: 0 | J7: 0 | K7: Dato del founder (10-sep-2026, Carlos Ochoa/DeUna): 2 % + IVA. Pendiente confirmar si practica retención de renta e IVA.
A8: Diferido 3 meses sin intereses (referencia, fuera de la mezcla) | B8: 0.06 | C8: 0.015 | D8: 0.04 | E8: =B8+C8*(1+$B$21) -> 0.07725 | F8: =D8*(1+$B$21) -> 0.046 | G8: =B8*$B$21/(1+$B$21)+C8*$B$21 -> 0.010076087 | H8: =D8*$B$21 -> 0.006 | I8: 1 | J8: 1 | K8: Calculadora Nuvei (hoja Diferido sin intereses)
A10: Mezcla de medios de pago (escenario) | B10: %
A11: Crédito corriente | B11: 0.45 | C11: SUPUESTO de lanzamiento. El i05 de la casa no mide esto: se ajusta con la mezcla real del primer mes.
A12: Débito | B12: 0.15
A13: DeUna | B13: 0.4
A14: Suma (debe ser 100 %) | B14: =SUM(B11:B13) -> 1
A15: Costo riel ponderado % (incl. IVA) | B15: =B11*E5+B12*E6+B13*E7 -> 0.042065
A16: Fijo ponderado $ (incl. IVA) | B16: =B11*F5+B12*F6+B13*F7 -> 0.0276
A17: IVA recuperable ponderado % | B17: =B11*G5+B12*G6+B13*G7 -> 0.0054867391
A18: IVA recuperable fijo ponderado $ | B18: =B11*H5+B12*H6+B13*H7 -> 0.0036
A20: Impuestos | B20: Valor | C20: Fuente
A21: IVA tarifa general | B21: 0.15 | C21: LRTI
A22: Retención renta que practican las emisoras de tarjeta (sobre base sin IVA) | B22: 0.02 | C22: Res. NAC-DGERCGC26-00000009 (mar-2026); calculadora Nuvei
A23: Retención IVA tarjetas — bienes (sobre el IVA) | B23: 0.3 | C23: Tabla de retención de IVA (emisoras a establecimientos afiliados)
A24: Retención IVA tarjetas — servicios y comisiones (sobre el IVA) | B24: 0.7 | C24: Ídem
A25: Impuesto a la renta régimen general (sobre utilidad) | B25: 0.25 | C25: LRTI sociedades
A26: RIMPE Emprendedor (sobre ingreso BRUTO, tramo 100–200k, referencial) | B26: 0.0175 | C26: Tabla RIMPE — hoy Satori Inov está en RIMPE (RUC 14-ago-2026); salir es decisión firmada
A27: Share de la mezcla que retiene renta | B27: =B11*I5+B12*I6+B13*I7 -> 0.6 | C27: fórmula
A28: Share de la mezcla que retiene IVA | B28: =B11*J5+B12*J6+B13*J7 -> 0.6 | C28: fórmula
A29: % prestadores de SERVICIO que facturan con IVA (dan crédito a Satori) | B29: 0.5 | C29: SUPUESTO — sale del relevamiento de la cohorte
A30: % vendedores de DESPENSA que facturan con IVA | B30: 1 | C30: SUPUESTO
A32: Costos variables por transacción | B32: Valor | C32: Fuente
A33: Mensajes WhatsApp (utility) por transacción | B33: 5 | C33: SUPUESTO: reserva + recordatorio + en camino + cierre + factura
A34: Costo por mensaje utility ($) | B34: 0.01 | C34: SUPUESTO — tarifa Meta para Ecuador; confirmar en el panel de WhatsApp
A35: Factura electrónica por documento ($) | B35: 0.05 | C35: epetplace-facturacion-sri.md §9 (mercado ~0,05)
A36: IA (NEXO) por transacción ($) | B36: 0.02 | C36: SUPUESTO — medir con el costo real de Anthropic del mes
A37: Reserva devoluciones y contracargos (% del total cobrado) | B37: 0.005 | C37: SUPUESTO prudente
A38: Costo variable fijo por transacción ($) | B38: =B33*B34+B35+B36 -> 0.12
A40: Costos fijos mensuales ($) — SIN sueldo del founder | B40: F&F (oct–dic 2026) | C40: Operación (desde ene-2027) | D40: Fuente / nota
A41: Infra: Supabase (Pro + compute + branching), Vercel Pro, EAS Production, Resend, Sentry, dominios, CDN | B41: 280 | C41: 330 | D41: SUPUESTO — reemplazar por facturas
A42: IA: Anthropic API en producción (NEXO, edges) + suscripciones Claude (metodología dual) | B42: 350 | C42: 500 | D42: SUPUESTO — hoy es el costo de construir; luego el de operar
A43: Herramientas: GitHub, Figma, Google Workspace, Apple/Google dev, WhatsApp Business/líneas, mapas y geocoding, SMS OTP | B43: 180 | C43: 250 | D43: SUPUESTO
A44: Facturación electrónica (plan) + firma electrónica | B44: 40 | C44: 60 | D44: Proveedor ~$25–50/mes + p12 prorrateado
A45: Contabilidad y cumplimiento (IVA mensual, ATS, retenciones, conciliación fiscal) | B45: 350 | C45: 450 | D45: SUPUESTO — cotizar con la firma contable
...

Sheet UE_Hoy
A1: UNIT ECONOMICS por transacción — HOY (10 %, sin tarifa de servicio)
A2: Una fila por vertical. Todo viene de Parametros. Contribución = ingreso de Satori − riel neto de IVA − costos variables. Las columnas de caja muestran lo que las tarjetas retienen y lo que queda atrapado.
A4: Vertical | B4: Modelo | C4: B/S | D4: Tarifa IVA | E4: Ticket base ($) | F4: IVA ítem ($) | G4: Tarifa servicio incl. IVA ($) | H4: Tarifa servicio base ($) | I4: IVA tarifa ($) | J4: TOTAL que paga la familia ($) | K4: Comisión % | L4: Comisión $ | M4: INGRESO SATORI base ($) | N4: Costo riel incl. IVA ($) | O4: IVA recuperable riel ($) | P4: Costo riel NETO ($) | Q4: Costos variables ($) | R4: CONTRIBUCIÓN ($) | S4: Contribución % del ticket | T4: Neto que recibe / factura el prestador ($) | U4: Retención renta (caja) ($) | V4: Retención IVA (caja) ($) | W4: IVA por pagar antes de retenciones ($) | X4: Exceso de retención IVA atrapado ($) | Y4: IVA a pagar en efectivo ($)
A5: =Parametros!A62 -> Paseo | B5: =Parametros!B62 -> reventa | C5: =Parametros!C62 -> S | D5: =Parametros!D62 -> 0.15 | E5: =Parametros!E62 -> 10 | F5: =E5*D5 -> 1.5 | G5: =Parametros!J62 -> 0 | H5: =G5/(1+Parametros!$B$21) -> 0 | I5: =G5-H5 -> 0 | J5: =E5+F5+G5 -> 11.5 | K5: =Parametros!F62 -> 0.1 | L5: =E5*K5 -> 1 | M5: =L5+H5 -> 1 | N5: =J5*Parametros!$B$15+Parametros!$B$16 -> 0.5113475 | O5: =IF(D5>0,J5*Parametros!$B$17+Parametros!$B$18,0) -> 0.0666975 | P5: =N5-O5 -> 0.44465 | Q5: =Parametros!$B$38+J5*Parametros!$B$37 -> 0.1775 | R5: =M5-P5-Q5 -> 0.37785 | S5: =IF(E5=0,0,R5/E5) -> 0.037785 | T5: =IF(B5="agencia",E5-L5*(1+Parametros!$B$21),E5-L5) -> 9 | U5: =Parametros!$B$27*Parametros!$B$22*IF(B5="agencia",M5,E5+H5) -> 0.12 | V5: =Parametros!$B$28*(IF(B5="agencia",0,F5*IF(C5="S",Parametros!$B$24,Parametros!$B$23))+I5*Parametros!$B$24) -> 0.63 | W5: =IF(B5="agencia",L5*Parametros!$B$21+I5,F5+I5-(E5-L5)*D5*IF(C5="S",Parametros!$B$29,Parametros!$B$30))-O5 -> 0.7583025 | X5: =MAX(V5-MAX(W5,0),0) -> 0 | Y5: =MAX(W5-V5,0) -> 0.1283025
A6: =Parametros!A63 -> Grooming | B6: =Parametros!B63 -> reventa | C6: =Parametros!C63 -> S | D6: =Parametros!D63 -> 0.15 | E6: =Parametros!E63 -> 25 | F6: =E6*D6 -> 3.75 | G6: =Parametros!J63 -> 0 | H6: =G6/(1+Parametros!$B$21) -> 0 | I6: =G6-H6 -> 0 | J6: =E6+F6+G6 -> 28.75 | K6: =Parametros!F63 -> 0.1 | L6: =E6*K6 -> 2.5 | M6: =L6+H6 -> 2.5 | N6: =J6*Parametros!$B$15+Parametros!$B$16 -> 1.2369687 | O6: =IF(D6>0,J6*Parametros!$B$17+Parametros!$B$18,0) -> 0.16134375 | P6: =N6-O6 -> 1.075625 | Q6: =Parametros!$B$38+J6*Parametros!$B$37 -> 0.26375 | R6: =M6-P6-Q6 -> 1.160625 | S6: =IF(E6=0,0,R6/E6) -> 0.046425 | T6: =IF(B6="agencia",E6-L6*(1+Parametros!$B$21),E6-L6) -> 22.5 | U6: =Parametros!$B$27*Parametros!$B$22*IF(B6="agencia",M6,E6+H6) -> 0.3 | V6: =Parametros!$B$28*(IF(B6="agencia",0,F6*IF(C6="S",Parametros!$B$24,Parametros!$B$23))+I6*Parametros!$B$24) -> 1.575 | W6: =IF(B6="agencia",L6*Parametros!$B$21+I6,F6+I6-(E6-L6)*D6*IF(C6="S",Parametros!$B$29,Parametros!$B$30))-O6 -> 1.9011563 | X6: =MAX(V6-MAX(W6,0),0) -> 0 | Y6: =MAX(W6-V6,0) -> 0.32615625
A7: =Parametros!A64 -> Guardería (día) | B7: =Parametros!B64 -> reventa | C7: =Parametros!C64 -> S | D7: =Parametros!D64 -> 0.15 | E7: =Parametros!E64 -> 18 | F7: =E7*D7 -> 2.7 | G7: =Parametros!J64 -> 0 | H7: =G7/(1+Parametros!$B$21) -> 0 | I7: =G7-H7 -> 0 | J7: =E7+F7+G7 -> 20.7 | K7: =Parametros!F64 -> 0.1 | L7: =E7*K7 -> 1.8 | M7: =L7+H7 -> 1.8 | N7: =J7*Parametros!$B$15+Parametros!$B$16 -> 0.8983455 | O7: =IF(D7>0,J7*Parametros!$B$17+Parametros!$B$18,0) -> 0.1171755 | P7: =N7-O7 -> 0.78117 | Q7: =Parametros!$B$38+J7*Parametros!$B$37 -> 0.2235 | R7: =M7-P7-Q7 -> 0.79533 | S7: =IF(E7=0,0,R7/E7) -> 0.044185 | T7: =IF(B7="agencia",E7-L7*(1+Parametros!$B$21),E7-L7) -> 16.2 | U7: =Parametros!$B$27*Parametros!$B$22*IF(B7="agencia",M7,E7+H7) -> 0.216 | V7: =Parametros!$B$28*(IF(B7="agencia",0,F7*IF(C7="S",Parametros!$B$24,Parametros!$B$23))+I7*Parametros!$B$24) -> 1.134 | W7: =IF(B7="agencia",L7*Parametros!$B$21+I7,F7+I7-(E7-L7)*D7*IF(C7="S",Parametros!$B$29,Parametros!$B$30))-O7 -> 1.3678245 | X7: =MAX(V7-MAX(W7,0),0) -> 0 | Y7: =MAX(W7-V7,0) -> 0.2338245
A8: =Parametros!A65 -> Adiestramiento (sesión) | B8: =Parametros!B65 -> reventa | C8: =Parametros!C65 -> S | D8: =Parametros!D65 -> 0.15 | E8: =Parametros!E65 -> 20 | F8: =E8*D8 -> 3 | G8: =Parametros!J65 -> 0 | H8: =G8/(1+Parametros!$B$21) -> 0 | I8: =G8-H8 -> 0 | J8: =E8+F8+G8 -> 23 | K8: =Parametros!F65 -> 0.1 | L8: =E8*K8 -> 2 | M8: =L8+H8 -> 2 | N8: =J8*Parametros!$B$15+Parametros!$B$16 -> 0.995095 | O8: =IF(D8>0,J8*Parametros!$B$17+Parametros!$B$18,0) -> 0.129795 | P8: =N8-O8 -> 0.8653 | Q8: =Parametros!$B$38+J8*Parametros!$B$37 -> 0.235 | R8: =M8-P8-Q8 -> 0.8997 | S8: =IF(E8=0,0,R8/E8) -> 0.044985 | T8: =IF(B8="agencia",E8-L8*(1+Parametros!$B$21),E8-L8) -> 18 | U8: =Parametros!$B$27*Parametros!$B$22*IF(B8="agencia",M8,E8+H8) -> 0.24 | V8: =Parametros!$B$28*(IF(B8="agencia",0,F8*IF(C8="S",Parametros!$B$24,Parametros!$B$23))+I8*Parametros!$B$24) -> 1.26 | W8: =IF(B8="agencia",L8*Parametros!$B$21+I8,F8+I8-(E8-L8)*D8*IF(C8="S",Parametros!$B$29,Parametros!$B$30))-O8 -> 1.520205 | X8: =MAX(V8-MAX(W8,0),0) -> 0 | Y8: =MAX(W8-V8,0) -> 0.260205
A9: =Parametros!A66 -> Veterinaria consulta | B9: =Parametros!B66 -> agencia | C9: =Parametros!C66 -> S | D9: =Parametros!D66 -> 0 | E9: =Parametros!E66 -> 40 | F9: =E9*D9 -> 0 | G9: =Parametros!J66 -> 0 | H9: =G9/(1+Parametros!$B$21) -> 0 | I9: =G9-H9 -> 0 | J9: =E9+F9+G9 -> 40 | K9: =Parametros!F66 -> 0.1 | L9: =E9*K9 -> 4 | M9: =L9+H9 -> 4 | N9: =J9*Parametros!$B$15+Parametros!$B$16 -> 1.7102 | O9: =IF(D9>0,J9*Parametros!$B$17+Parametros!$B$18,0) -> 0 | P9: =N9-O9 -> 1.7102 | Q9: =Parametros!$B$38+J9*Parametros!$B$37 -> 0.32 | R9: =M9-P9-Q9 -> 1.9698 | S9: =IF(E9=0,0,R9/E9) -> 0.049245 | T9: =IF(B9="agencia",E9-L9*(1+Parametros!$B$21),E9-L9) -> 35.4 | U9: =Parametros!$B$27*Parametros!$B$22*IF(B9="agencia",M9,E9+H9) -> 0.048 | V9: =Parametros!$B$28*(IF(B9="agencia",0,F9*IF(C9="S",Parametros!$B$24,Parametros!$B$23))+I9*Parametros!$B$24) -> 0 | W9: =IF(B9="agencia",L9*Parametros!$B$21+I9,F9+I9-(E9-L9)*D9*IF(C9="S",Parametros!$B$29,Parametros!$B$30))-O9 -> 0.6 | X9: =MAX(V9-MAX(W9,0),0) -> 0 | Y9: =MAX(W9-V9,0) -> 0.6
A10: =Parametros!A67 -> Telemedicina | B10: =Parametros!B67 -> agencia | C10: =Parametros!C67 -> S | D10: =Parametros!D67 -> 0 | E10: =Parametros!E67 -> 20 | F10: =E10*D10 -> 0 | G10: =Parametros!J67 -> 0 | H10: =G10/(1+Parametros!$B$21) -> 0 | I10: =G10-H10 -> 0 | J10: =E10+F10+G10 -> 20 | K10: =Parametros!F67 -> 0.1 | L10: =E10*K10 -> 2 | M10: =L10+H10 -> 2 | N10: =J10*Parametros!$B$15+Parametros!$B$16 -> 0.8689 | O10: =IF(D10>0,J10*Parametros!$B$17+Parametros!$B$18,0) -> 0 | P10: =N10-O10 -> 0.8689 | Q10: =Parametros!$B$38+J10*Parametros!$B$37 -> 0.22 | R10: =M10-P10-Q10 -> 0.9111 | S10: =IF(E10=0,0,R10/E10) -> 0.045555 | T10: =IF(B10="agencia",E10-L10*(1+Parametros!$B$21),E10-L10) -> 17.7 | U10: =Parametros!$B$27*Parametros!$B$22*IF(B10="agencia",M10,E10+H10) -> 0.024 | V10: =Parametros!$B$28*(IF(B10="agencia",0,F10*IF(C10="S",Parametros!$B$24,Parametros!$B$23))+I10*Parametros!$B$24) -> 0 | W10: =IF(B10="agencia",L10*Parametros!$B$21+I10,F10+I10-(E10-L10)*D10*IF(C10="S",Parametros!$B$29,Parametros!$B$30))-O10 -> 0.3 | X10: =MAX(V10-MAX(W10,0),0) -> 0 | Y10: =MAX(W10-V10,0) -> 0.3
A11: =Parametros!A68 -> Despensa — alimento balanceado | B11: =Parametros!B68 -> reventa | C11: =Parametros!C68 -> B | D11: =Parametros!D68 -> 0 | E11: =Parametros!E68 -> 45 | F11: =E11*D11 -> 0 | G11: =Parametros!J68 -> 0 | H11: =G11/(1+Parametros!$B$21) -> 0 | I11: =G11-H11 -> 0 | J11: =E11+F11+G11 -> 45 | K11: =Parametros!F68 -> 0.1 | L11: =E11*K11 -> 4.5 | M11: =L11+H11 -> 4.5 | N11: =J11*Parametros!$B$15+Parametros!$B$16 -> 1.920525 | O11: =IF(D11>0,J11*Parametros!$B$17+Parametros!$B$18,0) -> 0 | P11: =N11-O11 -> 1.920525 | Q11: =Parametros!$B$38+J11*Parametros!$B$37 -> 0.345 | R11: =M11-P11-Q11 -> 2.234475 | S11: =IF(E11=0,0,R11/E11) -> 0.049655 | T11: =IF(B11="agencia",E11-L11*(1+Parametros!$B$21),E11-L11) -> 40.5 | U11: =Parametros!$B$27*Parametros!$B$22*IF(B11="agencia",M11,E11+H11) -> 0.54 | V11: =Parametros!$B$28*(IF(B11="agencia",0,F11*IF(C11="S",Parametros!$B$24,Parametros!$B$23))+I11*Parametros!$B$24) -> 0 | W11: =IF(B11="agencia",L11*Parametros!$B$21+I11,F11+I11-(E11-L11)*D11*IF(C11="S",Parametros!$B$29,Parametros!$B$30))-O11 -> 0 | X11: =MAX(V11-MAX(W11,0),0) -> 0 | Y11: =MAX(W11-V11,0) -> 0
A12: =Parametros!A69 -> Despensa — snack / accesorio | B12: =Parametros!B69 -> reventa | C12: =Parametros!C69 -> B | D12: =Parametros!D69 -> 0.15 | E12: =Parametros!E69 -> 12 | F12: =E12*D12 -> 1.8 | G12: =Parametros!J69 -> 0 | H12: =G12/(1+Parametros!$B$21) -> 0 | I12: =G12-H12 -> 0 | J12: =E12+F12+G12 -> 13.8 | K12: =Parametros!F69 -> 0.1 | L12: =E12*K12 -> 1.2 | M12: =L12+H12 -> 1.2 | N12: =J12*Parametros!$B$15+Parametros!$B$16 -> 0.608097 | O12: =IF(D12>0,J12*Parametros!$B$17+Parametros!$B$18,0) -> 0.079317 | P12: =N12-O12 -> 0.52878 | Q12: =Parametros!$B$38+J12*Parametros!$B$37 -> 0.189 | R12: =M12-P12-Q12 -> 0.48222 | S12: =IF(E12=0,0,R12/E12) -> 0.040185 | T12: =IF(B12="agencia",E12-L12*(1+Parametros!$B$21),E12-L12) -> 10.8 | U12: =Parametros!$B$27*Parametros!$B$22*IF(B12="agencia",M12,E12+H12) -> 0.144 | V12: =Parametros!$B$28*(IF(B12="agencia",0,F12*IF(C12="S",Parametros!$B$24,Parametros!$B$23))+I12*Parametros!$B$24) -> 0.324 | W12: =IF(B12="agencia",L12*Parametros!$B$21+I12,F12+I12-(E12-L12)*D12*IF(C12="S",Parametros!$B$29,Parametros!$B$30))-O12 -> 0.100683 | X12: =MAX(V12-MAX(W12,0),0) -> 0.223317 | Y12: =MAX(W12-V12,0) -> 0
A13: =Parametros!A70 -> Paquete 10 paseos (prepago) | B13: =Parametros!B70 -> reventa | C13: =Parametros!C70 -> S | D13: =Parametros!D70 -> 0.15 | E13: =Parametros!E70 -> 95 | F13: =E13*D13 -> 14.25 | G13: =Parametros!J70 -> 0 | H13: =G13/(1+Parametros!$B$21) -> 0 | I13: =G13-H13 -> 0 | J13: =E13+F13+G13 -> 109.25 | K13: =Parametros!F70 -> 0.1 | L13: =E13*K13 -> 9.5 | M13: =L13+H13 -> 9.5 | N13: =J13*Parametros!$B$15+Parametros!$B$16 -> 4.6232013 | O13: =IF(D13>0,J13*Parametros!$B$17+Parametros!$B$18,0) -> 0.60302625 | P13: =N13-O13 -> 4.020175 | Q13: =Parametros!$B$38+J13*Parametros!$B$37 -> 0.66625 | R13: =M13-P13-Q13 -> 4.813575 | S13: =IF(E13=0,0,R13/E13) -> 0.050669211 | T13: =IF(B13="agencia",E13-L13*(1+Parametros!$B$21),E13-L13) -> 85.5 | U13: =Parametros!$B$27*Parametros!$B$22*IF(B13="agencia",M13,E13+H13) -> 1.14 | V13: =Parametros!$B$28*(IF(B13="agencia",0,F13*IF(C13="S",Parametros!$B$24,Parametros!$B$23))+I13*Parametros!$B$24) -> 5.985 | W13: =IF(B13="agencia",L13*Parametros!$B$21+I13,F13+I13-(E13-L13)*D13*IF(C13="S",Parametros!$B$29,Parametros!$B$30))-O13 -> 7.2344738 | X13: =MAX(V13-MAX(W13,0),0) -> 0 | Y13: =MAX(W13-V13,0) -> 1.2494737
A15: Lectura: la contribución es lo que queda para pagar los costos fijos y al founder. Con riel 100 % tarjeta de crédito, cambiá la mezcla en Parametros y mirá esta columna.
A16: Simplificaciones declaradas: el IVA del riel se toma recuperable solo cuando el ítem está gravado (proporcionalidad aproximada); en agencia la retención sobre la parte de la clínica se neutraliza porque Satori re-retiene a la clínica (régimen de mercados en línea) y no se muestra; el envío de despensa no está modelado.

Sheet UE_Propuesta
A1: UNIT ECONOMICS por transacción — PROPUESTA (comisión por vertical + mínimo + tarifa de servicio)
A2: Una fila por vertical. Todo viene de Parametros. Contribución = ingreso de Satori − riel neto de IVA − costos variables. Las columnas de caja muestran lo que las tarjetas retienen y lo que queda atrapado.
A4: Vertical | B4: Modelo | C4: B/S | D4: Tarifa IVA | E4: Ticket base ($) | F4: IVA ítem ($) | G4: Tarifa servicio incl. IVA ($) | H4: Tarifa servicio base ($) | I4: IVA tarifa ($) | J4: TOTAL que paga la familia ($) | K4: Comisión % | L4: Comisión $ | M4: INGRESO SATORI base ($) | N4: Costo riel incl. IVA ($) | O4: IVA recuperable riel ($) | P4: Costo riel NETO ($) | Q4: Costos variables ($) | R4: CONTRIBUCIÓN ($) | S4: Contribución % del ticket | T4: Neto que recibe / factura el prestador ($) | U4: Retención renta (caja) ($) | V4: Retención IVA (caja) ($) | W4: IVA por pagar antes de retenciones ($) | X4: Exceso de retención IVA atrapado ($) | Y4: IVA a pagar en efectivo ($)
A5: =Parametros!A62 -> Paseo | B5: =Parametros!B62 -> reventa | C5: =Parametros!C62 -> S | D5: =Parametros!D62 -> 0.15 | E5: =Parametros!E62 -> 10 | F5: =E5*D5 -> 1.5 | G5: =Parametros!I62 -> 0.99 | H5: =G5/(1+Parametros!$B$21) -> 0.86086957 | I5: =G5-H5 -> 0.12913043 | J5: =E5+F5+G5 -> 12.49 | K5: =Parametros!G62 -> 0.18 | L5: =MAX(E5*K5,Parametros!H62) -> 1.8 | M5: =L5+H5 -> 2.6608696 | N5: =J5*Parametros!$B$15+Parametros!$B$16 -> 0.55299185 | O5: =IF(D5>0,J5*Parametros!$B$17+Parametros!$B$18,0) -> 0.072129372 | P5: =N5-O5 -> 0.48086248 | Q5: =Parametros!$B$38+J5*Parametros!$B$37 -> 0.18245 | R5: =M5-P5-Q5 -> 1.9975571 | S5: =IF(E5=0,0,R5/E5) -> 0.19975571 | T5: =IF(B5="agencia",E5-L5*(1+Parametros!$B$21),E5-L5) -> 8.2 | U5: =Parametros!$B$27*Parametros!$B$22*IF(B5="agencia",M5,E5+H5) -> 0.13033043 | V5: =Parametros!$B$28*(IF(B5="agencia",0,F5*IF(C5="S",Parametros!$B$24,Parametros!$B$23))+I5*Parametros!$B$24) -> 0.68423478 | W5: =IF(B5="agencia",L5*Parametros!$B$21+I5,F5+I5-(E5-L5)*D5*IF(C5="S",Parametros!$B$29,Parametros!$B$30))-O5 -> 0.94200106 | X5: =MAX(V5-MAX(W5,0),0) -> 0 | Y5: =MAX(W5-V5,0) -> 0.25776628
A6: =Parametros!A63 -> Grooming | B6: =Parametros!B63 -> reventa | C6: =Parametros!C63 -> S | D6: =Parametros!D63 -> 0.15 | E6: =Parametros!E63 -> 25 | F6: =E6*D6 -> 3.75 | G6: =Parametros!I63 -> 0.99 | H6: =G6/(1+Parametros!$B$21) -> 0.86086957 | I6: =G6-H6 -> 0.12913043 | J6: =E6+F6+G6 -> 29.74 | K6: =Parametros!G63 -> 0.18 | L6: =MAX(E6*K6,Parametros!H63) -> 4.5 | M6: =L6+H6 -> 5.3608696 | N6: =J6*Parametros!$B$15+Parametros!$B$16 -> 1.2786131 | O6: =IF(D6>0,J6*Parametros!$B$17+Parametros!$B$18,0) -> 0.16677562 | P6: =N6-O6 -> 1.1118375 | Q6: =Parametros!$B$38+J6*Parametros!$B$37 -> 0.2687 | R6: =M6-P6-Q6 -> 3.9803321 | S6: =IF(E6=0,0,R6/E6) -> 0.15921328 | T6: =IF(B6="agencia",E6-L6*(1+Parametros!$B$21),E6-L6) -> 20.5 | U6: =Parametros!$B$27*Parametros!$B$22*IF(B6="agencia",M6,E6+H6) -> 0.31033043 | V6: =Parametros!$B$28*(IF(B6="agencia",0,F6*IF(C6="S",Parametros!$B$24,Parametros!$B$23))+I6*Parametros!$B$24) -> 1.6292348 | W6: =IF(B6="agencia",L6*Parametros!$B$21+I6,F6+I6-(E6-L6)*D6*IF(C6="S",Parametros!$B$29,Parametros!$B$30))-O6 -> 2.1748548 | X6: =MAX(V6-MAX(W6,0),0) -> 0 | Y6: =MAX(W6-V6,0) -> 0.54562003
A7: =Parametros!A64 -> Guardería (día) | B7: =Parametros!B64 -> reventa | C7: =Parametros!C64 -> S | D7: =Parametros!D64 -> 0.15 | E7: =Parametros!E64 -> 18 | F7: =E7*D7 -> 2.7 | G7: =Parametros!I64 -> 0.99 | H7: =G7/(1+Parametros!$B$21) -> 0.86086957 | I7: =G7-H7 -> 0.12913043 | J7: =E7+F7+G7 -> 21.69 | K7: =Parametros!G64 -> 0.18 | L7: =MAX(E7*K7,Parametros!H64) -> 3.24 | M7: =L7+H7 -> 4.1008696 | N7: =J7*Parametros!$B$15+Parametros!$B$16 -> 0.93998985 | O7: =IF(D7>0,J7*Parametros!$B$17+Parametros!$B$18,0) -> 0.12260737 | P7: =N7-O7 -> 0.81738248 | Q7: =Parametros!$B$38+J7*Parametros!$B$37 -> 0.22845 | R7: =M7-P7-Q7 -> 3.0550371 | S7: =IF(E7=0,0,R7/E7) -> 0.16972428 | T7: =IF(B7="agencia",E7-L7*(1+Parametros!$B$21),E7-L7) -> 14.76 | U7: =Parametros!$B$27*Parametros!$B$22*IF(B7="agencia",M7,E7+H7) -> 0.22633043 | V7: =Parametros!$B$28*(IF(B7="agencia",0,F7*IF(C7="S",Parametros!$B$24,Parametros!$B$23))+I7*Parametros!$B$24) -> 1.1882348 | W7: =IF(B7="agencia",L7*Parametros!$B$21+I7,F7+I7-(E7-L7)*D7*IF(C7="S",Parametros!$B$29,Parametros!$B$30))-O7 -> 1.5995231 | X7: =MAX(V7-MAX(W7,0),0) -> 0 | Y7: =MAX(W7-V7,0) -> 0.41128828
A8: =Parametros!A65 -> Adiestramiento (sesión) | B8: =Parametros!B65 -> reventa | C8: =Parametros!C65 -> S | D8: =Parametros!D65 -> 0.15 | E8: =Parametros!E65 -> 20 | F8: =E8*D8 -> 3 | G8: =Parametros!I65 -> 0.99 | H8: =G8/(1+Parametros!$B$21) -> 0.86086957 | I8: =G8-H8 -> 0.12913043 | J8: =E8+F8+G8 -> 23.99 | K8: =Parametros!G65 -> 0.18 | L8: =MAX(E8*K8,Parametros!H65) -> 3.6 | M8: =L8+H8 -> 4.4608696 | N8: =J8*Parametros!$B$15+Parametros!$B$16 -> 1.0367393 | O8: =IF(D8>0,J8*Parametros!$B$17+Parametros!$B$18,0) -> 0.13522687 | P8: =N8-O8 -> 0.90151248 | Q8: =Parametros!$B$38+J8*Parametros!$B$37 -> 0.23995 | R8: =M8-P8-Q8 -> 3.3194071 | S8: =IF(E8=0,0,R8/E8) -> 0.16597035 | T8: =IF(B8="agencia",E8-L8*(1+Parametros!$B$21),E8-L8) -> 16.4 | U8: =Parametros!$B$27*Parametros!$B$22*IF(B8="agencia",M8,E8+H8) -> 0.25033043 | V8: =Parametros!$B$28*(IF(B8="agencia",0,F8*IF(C8="S",Parametros!$B$24,Parametros!$B$23))+I8*Parametros!$B$24) -> 1.3142348 | W8: =IF(B8="agencia",L8*Parametros!$B$21+I8,F8+I8-(E8-L8)*D8*IF(C8="S",Parametros!$B$29,Parametros!$B$30))-O8 -> 1.7639036 | X8: =MAX(V8-MAX(W8,0),0) -> 0 | Y8: =MAX(W8-V8,0) -> 0.44966878
A9: =Parametros!A66 -> Veterinaria consulta | B9: =Parametros!B66 -> agencia | C9: =Parametros!C66 -> S | D9: =Parametros!D66 -> 0 | E9: =Parametros!E66 -> 40 | F9: =E9*D9 -> 0 | G9: =Parametros!I66 -> 0.99 | H9: =G9/(1+Parametros!$B$21) -> 0.86086957 | I9: =G9-H9 -> 0.12913043 | J9: =E9+F9+G9 -> 40.99 | K9: =Parametros!G66 -> 0.12 | L9: =MAX(E9*K9,Parametros!H66) -> 4.8 | M9: =L9+H9 -> 5.6608696 | N9: =J9*Parametros!$B$15+Parametros!$B$16 -> 1.7518444 | O9: =IF(D9>0,J9*Parametros!$B$17+Parametros!$B$18,0) -> 0 | P9: =N9-O9 -> 1.7518444 | Q9: =Parametros!$B$38+J9*Parametros!$B$37 -> 0.32495 | R9: =M9-P9-Q9 -> 3.5840752 | S9: =IF(E9=0,0,R9/E9) -> 0.08960188 | T9: =IF(B9="agencia",E9-L9*(1+Parametros!$B$21),E9-L9) -> 34.48 | U9: =Parametros!$B$27*Parametros!$B$22*IF(B9="agencia",M9,E9+H9) -> 0.067930435 | V9: =Parametros!$B$28*(IF(B9="agencia",0,F9*IF(C9="S",Parametros!$B$24,Parametros!$B$23))+I9*Parametros!$B$24) -> 0.054234783 | W9: =IF(B9="agencia",L9*Parametros!$B$21+I9,F9+I9-(E9-L9)*D9*IF(C9="S",Parametros!$B$29,Parametros!$B$30))-O9 -> 0.84913043 | X9: =MAX(V9-MAX(W9,0),0) -> 0 | Y9: =MAX(W9-V9,0) -> 0.79489565
A10: =Parametros!A67 -> Telemedicina | B10: =Parametros!B67 -> agencia | C10: =Parametros!C67 -> S | D10: =Parametros!D67 -> 0 | E10: =Parametros!E67 -> 20 | F10: =E10*D10 -> 0 | G10: =Parametros!I67 -> 0.99 | H10: =G10/(1+Parametros!$B$21) -> 0.86086957 | I10: =G10-H10 -> 0.12913043 | J10: =E10+F10+G10 -> 20.99 | K10: =Parametros!G67 -> 0.12 | L10: =MAX(E10*K10,Parametros!H67) -> 2.4 | M10: =L10+H10 -> 3.2608696 | N10: =J10*Parametros!$B$15+Parametros!$B$16 -> 0.91054435 | O10: =IF(D10>0,J10*Parametros!$B$17+Parametros!$B$18,0) -> 0 | P10: =N10-O10 -> 0.91054435 | Q10: =Parametros!$B$38+J10*Parametros!$B$37 -> 0.22495 | R10: =M10-P10-Q10 -> 2.1253752 | S10: =IF(E10=0,0,R10/E10) -> 0.10626876 | T10: =IF(B10="agencia",E10-L10*(1+Parametros!$B$21),E10-L10) -> 17.24 | U10: =Parametros!$B$27*Parametros!$B$22*IF(B10="agencia",M10,E10+H10) -> 0.039130435 | V10: =Parametros!$B$28*(IF(B10="agencia",0,F10*IF(C10="S",Parametros!$B$24,Parametros!$B$23))+I10*Parametros!$B$24) -> 0.054234783 | W10: =IF(B10="agencia",L10*Parametros!$B$21+I10,F10+I10-(E10-L10)*D10*IF(C10="S",Parametros!$B$29,Parametros!$B$30))-O10 -> 0.48913043 | X10: =MAX(V10-MAX(W10,0),0) -> 0 | Y10: =MAX(W10-V10,0) -> 0.43489565
A11: =Parametros!A68 -> Despensa — alimento balanceado | B11: =Parametros!B68 -> reventa | C11: =Parametros!C68 -> B | D11: =Parametros!D68 -> 0 | E11: =Parametros!E68 -> 45 | F11: =E11*D11 -> 0 | G11: =Parametros!I68 -> 0.99 | H11: =G11/(1+Parametros!$B$21) -> 0.86086957 | I11: =G11-H11 -> 0.12913043 | J11: =E11+F11+G11 -> 45.99 | K11: =Parametros!G68 -> 0.15 | L11: =MAX(E11*K11,Parametros!H68) -> 6.75 | M11: =L11+H11 -> 7.6108696 | N11: =J11*Parametros!$B$15+Parametros!$B$16 -> 1.9621693 | O11: =IF(D11>0,J11*Parametros!$B$17+Parametros!$B$18,0) -> 0 | P11: =N11-O11 -> 1.9621693 | Q11: =Parametros!$B$38+J11*Parametros!$B$37 -> 0.34995 | R11: =M11-P11-Q11 -> 5.2987502 | S11: =IF(E11=0,0,R11/E11) -> 0.11775 | T11: =IF(B11="agencia",E11-L11*(1+Parametros!$B$21),E11-L11) -> 38.25 | U11: =Parametros!$B$27*Parametros!$B$22*IF(B11="agencia",M11,E11+H11) -> 0.55033043 | V11: =Parametros!$B$28*(IF(B11="agencia",0,F11*IF(C11="S",Parametros!$B$24,Parametros!$B$23))+I11*Parametros!$B$24) -> 0.054234783 | W11: =IF(B11="agencia",L11*Parametros!$B$21+I11,F11+I11-(E11-L11)*D11*IF(C11="S",Parametros!$B$29,Parametros!$B$30))-O11 -> 0.12913043 | X11: =MAX(V11-MAX(W11,0),0) -> 0 | Y11: =MAX(W11-V11,0) -> 0.074895652
A12: =Parametros!A69 -> Despensa — snack / accesorio | B12: =Parametros!B69 -> reventa | C12: =Parametros!C69 -> B | D12: =Parametros!D69 -> 0.15 | E12: =Parametros!E69 -> 12 | F12: =E12*D12 -> 1.8 | G12: =Parametros!I69 -> 0.99 | H12: =G12/(1+Parametros!$B$21) -> 0.86086957 | I12: =G12-H12 -> 0.12913043 | J12: =E12+F12+G12 -> 14.79 | K12: =Parametros!G69 -> 0.15 | L12: =MAX(E12*K12,Parametros!H69) -> 1.8 | M12: =L12+H12 -> 2.6608696 | N12: =J12*Parametros!$B$15+Parametros!$B$16 -> 0.64974135 | O12: =IF(D12>0,J12*Parametros!$B$17+Parametros!$B$18,0) -> 0.084748872 | P12: =N12-O12 -> 0.56499248 | Q12: =Parametros!$B$38+J12*Parametros!$B$37 -> 0.19395 | R12: =M12-P12-Q12 -> 1.9019271 | S12: =IF(E12=0,0,R12/E12) -> 0.15849392 | T12: =IF(B12="agencia",E12-L12*(1+Parametros!$B$21),E12-L12) -> 10.2 | U12: =Parametros!$B$27*Parametros!$B$22*IF(B12="agencia",M12,E12+H12) -> 0.15433043 | V12: =Parametros!$B$28*(IF(B12="agencia",0,F12*IF(C12="S",Parametros!$B$24,Parametros!$B$23))+I12*Parametros!$B$24) -> 0.37823478 | W12: =IF(B12="agencia",L12*Parametros!$B$21+I12,F12+I12-(E12-L12)*D12*IF(C12="S",Parametros!$B$29,Parametros!$B$30))-O12 -> 0.31438156 | X12: =MAX(V12-MAX(W12,0),0) -> 0.06385322 | Y12: =MAX(W12-V12,0) -> 0
A13: =Parametros!A70 -> Paquete 10 paseos (prepago) | B13: =Parametros!B70 -> reventa | C13: =Parametros!C70 -> S | D13: =Parametros!D70 -> 0.15 | E13: =Parametros!E70 -> 95 | F13: =E13*D13 -> 14.25 | G13: =Parametros!I70 -> 0.99 | H13: =G13/(1+Parametros!$B$21) -> 0.86086957 | I13: =G13-H13 -> 0.12913043 | J13: =E13+F13+G13 -> 110.24 | K13: =Parametros!G70 -> 0.18 | L13: =MAX(E13*K13,Parametros!H70) -> 17.1 | M13: =L13+H13 -> 17.96087 | N13: =J13*Parametros!$B$15+Parametros!$B$16 -> 4.6648456 | O13: =IF(D13>0,J13*Parametros!$B$17+Parametros!$B$18,0) -> 0.60845812 | P13: =N13-O13 -> 4.0563875 | Q13: =Parametros!$B$38+J13*Parametros!$B$37 -> 0.6712 | R13: =M13-P13-Q13 -> 13.233282 | S13: =IF(E13=0,0,R13/E13) -> 0.13929771 | T13: =IF(B13="agencia",E13-L13*(1+Parametros!$B$21),E13-L13) -> 77.9 | U13: =Parametros!$B$27*Parametros!$B$22*IF(B13="agencia",M13,E13+H13) -> 1.1503304 | V13: =Parametros!$B$28*(IF(B13="agencia",0,F13*IF(C13="S",Parametros!$B$24,Parametros!$B$23))+I13*Parametros!$B$24) -> 6.0392348 | W13: =IF(B13="agencia",L13*Parametros!$B$21+I13,F13+I13-(E13-L13)*D13*IF(C13="S",Parametros!$B$29,Parametros!$B$30))-O13 -> 7.9281723 | X13: =MAX(V13-MAX(W13,0),0) -> 0 | Y13: =MAX(W13-V13,0) -> 1.8889375
A15: Lectura: la contribución es lo que queda para pagar los costos fijos y al founder. Con riel 100 % tarjeta de crédito, cambiá la mezcla en Parametros y mirá esta columna.
A16: Simplificaciones declaradas: el IVA del riel se toma recuperable solo cuando el ítem está gravado (proporcionalidad aproximada); en agencia la retención sobre la parte de la clínica se neutraliza porque Satori re-retiene a la clínica (régimen de mercados en línea) y no se muestra; el envío de despensa no está modelado.

Sheet PyL_mensual
A1: P&L MENSUAL — 12 meses desde el lanzamiento (oct-2026 → sep-2027)
A2: Volúmenes del mes 1 en azul (SUPUESTO F&F); los meses siguientes crecen con la tasa de B3. Dos bloques: HOY vs PROPUESTA, sobre los mismos volúmenes.
A3: Crecimiento mensual del volumen | B3: 0.15
A4: Fase del mes (1 = F&F, 2 = Operación) | C4: 1 | D4: 1 | E4: 1 | F4: 2 | G4: 2 | H4: 2 | I4: 2 | J4: 2 | K4: 2 | L4: 2 | M4: 2 | N4: 2
A5: Transacciones por vertical | B5: Mes 1 (input) | C5: oct-26 | D5: nov-26 | E5: dic-26 | F5: ene-27 | G5: feb-27 | H5: mar-27 | I5: abr-27 | J5: may-27 | K5: jun-27 | L5: jul-27 | M5: ago-27 | N5: sep-27
A6: =Parametros!A62 -> Paseo | B6: 60 | C6: =$B6 -> 60 | D6: =C6*(1+$B$3) -> 69 | E6: =D6*(1+$B$3) -> 79.35 | F6: =E6*(1+$B$3) -> 91.2525 | G6: =F6*(1+$B$3) -> 104.94038 | H6: =G6*(1+$B$3) -> 120.68143 | I6: =H6*(1+$B$3) -> 138.78365 | J6: =I6*(1+$B$3) -> 159.60119 | K6: =J6*(1+$B$3) -> 183.54137 | ... N6: =M6*(1+$B$3) -> 279.14348
A7: =Parametros!A63 -> Grooming | B7: 20 | C7: =$B7 -> 20 | D7: =C7*(1+$B$3) -> 23 | E7: =D7*(1+$B$3) -> 26.45 | F7: =E7*(1+$B$3) -> 30.4175 | G7: =F7*(1+$B$3) -> 34.980125 | H7: =G7*(1+$B$3) -> 40.227144 | I7: =H7*(1+$B$3) -> 46.261215 | J7: =I7*(1+$B$3) -> 53.200398 | K7: =J7*(1+$B$3) -> 61.180457 | ... N7: =M7*(1+$B$3) -> 93.047828
A8: =Parametros!A64 -> Guardería (día) | B8: 10 | C8: =$B8 -> 10 | D8: =C8*(1+$B$3) -> 11.5 | E8: =D8*(1+$B$3) -> 13.225 | F8: =E8*(1+$B$3) -> 15.20875 | G8: =F8*(1+$B$3) -> 17.490063 | H8: =G8*(1+$B$3) -> 20.113572 | I8: =H8*(1+$B$3) -> 23.130608 | J8: =I8*(1+$B$3) -> 26.600199 | K8: =J8*(1+$B$3) -> 30.590229 | ... N8: =M8*(1+$B$3) -> 46.523914
A9: =Parametros!A65 -> Adiestramiento (sesión) | B9: 5 | C9: =$B9 -> 5 | D9: =C9*(1+$B$3) -> 5.75 | E9: =D9*(1+$B$3) -> 6.6125 | F9: =E9*(1+$B$3) -> 7.604375 | G9: =F9*(1+$B$3) -> 8.7450313 | H9: =G9*(1+$B$3) -> 10.056786 | I9: =H9*(1+$B$3) -> 11.565304 | J9: =I9*(1+$B$3) -> 13.300099 | K9: =J9*(1+$B$3) -> 15.295114 | ... N9: =M9*(1+$B$3) -> 23.261957
A10: =Parametros!A66 -> Veterinaria consulta | B10: 25 | C10: =$B10 -> 25 | D10: =C10*(1+$B$3) -> 28.75 | E10: =D10*(1+$B$3) -> 33.0625 | F10: =E10*(1+$B$3) -> 38.021875 | G10: =F10*(1+$B$3) -> 43.725156 | H10: =G10*(1+$B$3) -> 50.28393 | I10: =H10*(1+$B$3) -> 57.826519 | J10: =I10*(1+$B$3) -> 66.500497 | K10: =J10*(1+$B$3) -> 76.475572 | ... N10: =M10*(1+$B$3) -> 116.30978
A11: =Parametros!A67 -> Telemedicina | B11: 5 | C11: =$B11 -> 5 | D11: =C11*(1+$B$3) -> 5.75 | E11: =D11*(1+$B$3) -> 6.6125 | F11: =E11*(1+$B$3) -> 7.604375 | G11: =F11*(1+$B$3) -> 8.7450313 | H11: =G11*(1+$B$3) -> 10.056786 | I11: =H11*(1+$B$3) -> 11.565304 | J11: =I11*(1+$B$3) -> 13.300099 | K11: =J11*(1+$B$3) -> 15.295114 | ... N11: =M11*(1+$B$3) -> 23.261957
A12: =Parametros!A68 -> Despensa — alimento balanceado | B12: 30 | C12: =$B12 -> 30 | D12: =C12*(1+$B$3) -> 34.5 | E12: =D12*(1+$B$3) -> 39.675 | F12: =E12*(1+$B$3) -> 45.62625 | G12: =F12*(1+$B$3) -> 52.470188 | H12: =G12*(1+$B$3) -> 60.340716 | I12: =H12*(1+$B$3) -> 69.391823 | J12: =I12*(1+$B$3) -> 79.800596 | K12: =J12*(1+$B$3) -> 91.770686 | ... N12: =M12*(1+$B$3) -> 139.57174
A13: =Parametros!A69 -> Despensa — snack / accesorio | B13: 40 | C13: =$B13 -> 40 | D13: =C13*(1+$B$3) -> 46 | E13: =D13*(1+$B$3) -> 52.9 | F13: =E13*(1+$B$3) -> 60.835 | G13: =F13*(1+$B$3) -> 69.96025 | H13: =G13*(1+$B$3) -> 80.454288 | I13: =H13*(1+$B$3) -> 92.522431 | J13: =I13*(1+$B$3) -> 106.4008 | K13: =J13*(1+$B$3) -> 122.36091 | ... N13: =M13*(1+$B$3) -> 186.09566
A14: =Parametros!A70 -> Paquete 10 paseos (prepago) | B14: 3 | C14: =$B14 -> 3 | D14: =C14*(1+$B$3) -> 3.45 | E14: =D14*(1+$B$3) -> 3.9675 | F14: =E14*(1+$B$3) -> 4.562625 | G14: =F14*(1+$B$3) -> 5.2470187 | H14: =G14*(1+$B$3) -> 6.0340716 | I14: =H14*(1+$B$3) -> 6.9391823 | J14: =I14*(1+$B$3) -> 7.9800596 | K14: =J14*(1+$B$3) -> 9.1770686 | ... N14: =M14*(1+$B$3) -> 13.957174
A15: Total transacciones | C15: =SUM(C6:C14) -> 198 | D15: =SUM(D6:D14) -> 227.7 | E15: =SUM(E6:E14) -> 261.855 | F15: =SUM(F6:F14) -> 301.13325 | G15: =SUM(G6:G14) -> 346.30324 | H15: =SUM(H6:H14) -> 398.24872 | I15: =SUM(I6:I14) -> 457.98603 | J15: =SUM(J6:J14) -> 526.68394 | ... N15: =SUM(N6:N14) -> 921.1735
A17: ESCENARIO HOY — comisión 10 %, sin tarifa de servicio
A18: GMV — total pagado por las familias ($) | C18: =SUMPRODUCT(C$6:C$14,UE_Hoy!$J$5:$J$13) -> 4916.75 | D18: =SUMPRODUCT(D$6:D$14,UE_Hoy!$J$5:$J$13) -> 5654.2625 | E18: =SUMPRODUCT(E$6:E$14,UE_Hoy!$J$5:$J$13) -> 6502.4019 | F18: =SUMPRODUCT(F$6:F$14,UE_Hoy!$J$5:$J$13) -> 7477.7622 | G18: =SUMPRODUCT(G$6:G$14,UE_Hoy!$J$5:$J$13) -> 8599.4265 | H18: =SUMPRODUCT(H$6:H$14,UE_Hoy!$J$5:$J$13) -> 9889.3405 | I18: =SUMPRODUCT(I$6:I$14,UE_Hoy!$J$5:$J$13) -> 11372.742 | J18: =SUMPRODUCT(J$6:J$14,UE_Hoy!$J$5:$J$13) -> 13078.653 | ... N18: =SUMPRODUCT(N$6:N$14,UE_Hoy!$J$5:$J$13) -> 22874.645
A19: Ingreso de Satori (comisiones + tarifa de servicio, base) ($) | C19: =SUMPRODUCT(C$6:C$14,UE_Hoy!$M$5:$M$13) -> 459.5 | D19: =SUMPRODUCT(D$6:D$14,UE_Hoy!$M$5:$M$13) -> 528.425 | E19: =SUMPRODUCT(E$6:E$14,UE_Hoy!$M$5:$M$13) -> 607.68875 | F19: =SUMPRODUCT(F$6:F$14,UE_Hoy!$M$5:$M$13) -> 698.84206 | G19: =SUMPRODUCT(G$6:G$14,UE_Hoy!$M$5:$M$13) -> 803.66837 | H19: =SUMPRODUCT(H$6:H$14,UE_Hoy!$M$5:$M$13) -> 924.21863 | I19: =SUMPRODUCT(I$6:I$14,UE_Hoy!$M$5:$M$13) -> 1062.8514 | J19: =SUMPRODUCT(J$6:J$14,UE_Hoy!$M$5:$M$13) -> 1222.2791 | ... N19: =SUMPRODUCT(N$6:N$14,UE_Hoy!$M$5:$M$13) -> 2137.7738
A20: Costo del riel neto de IVA ($) | C20: =SUMPRODUCT(C$6:C$14,UE_Hoy!$P$5:$P$13) -> 198.25668 | D20: =SUMPRODUCT(D$6:D$14,UE_Hoy!$P$5:$P$13) -> 227.99518 | E20: =SUMPRODUCT(E$6:E$14,UE_Hoy!$P$5:$P$13) -> 262.19445 | F20: =SUMPRODUCT(F$6:F$14,UE_Hoy!$P$5:$P$13) -> 301.52362 | G20: =SUMPRODUCT(G$6:G$14,UE_Hoy!$P$5:$P$13) -> 346.75216 | H20: =SUMPRODUCT(H$6:H$14,UE_Hoy!$P$5:$P$13) -> 398.76499 | I20: =SUMPRODUCT(I$6:I$14,UE_Hoy!$P$5:$P$13) -> 458.57974 | J20: =SUMPRODUCT(J$6:J$14,UE_Hoy!$P$5:$P$13) -> 527.3667 | ... N20: =SUMPRODUCT(N$6:N$14,UE_Hoy!$P$5:$P$13) -> 922.36765
A21: Costos variables ($) | C21: =SUMPRODUCT(C$6:C$14,UE_Hoy!$Q$5:$Q$13) -> 48.34375 | D21: =SUMPRODUCT(D$6:D$14,UE_Hoy!$Q$5:$Q$13) -> 55.595312 | E21: =SUMPRODUCT(E$6:E$14,UE_Hoy!$Q$5:$Q$13) -> 63.934609 | F21: =SUMPRODUCT(F$6:F$14,UE_Hoy!$Q$5:$Q$13) -> 73.524801 | G21: =SUMPRODUCT(G$6:G$14,UE_Hoy!$Q$5:$Q$13) -> 84.553521 | H21: =SUMPRODUCT(H$6:H$14,UE_Hoy!$Q$5:$Q$13) -> 97.236549 | I21: =SUMPRODUCT(I$6:I$14,UE_Hoy!$Q$5:$Q$13) -> 111.82203 | J21: =SUMPRODUCT(J$6:J$14,UE_Hoy!$Q$5:$Q$13) -> 128.59534 | ... N21: =SUMPRODUCT(N$6:N$14,UE_Hoy!$Q$5:$Q$13) -> 224.91405
A22: CONTRIBUCIÓN transaccional + suscripciones ($) | C22: =C19-C20-C21+C$46 -> 212.89957 | D22: =D19-D20-D21+D$46 -> 244.83451 | E22: =E19-E20-E21+E$46 -> 281.55969 | F22: =F19-F20-F21+F$46 -> 323.79364 | G22: =G19-G20-G21+G$46 -> 372.36269 | H22: =H19-H20-H21+H$46 -> 428.21709 | I22: =I19-I20-I21+I$46 -> 492.44965 | J22: =J19-J20-J21+J$46 -> 566.3171 | ... N22: =N19-N20-N21+N$46 -> 990.49215
A23: Costos fijos del escenario ($) | C23: =IF(C$4=1,Parametros!$B$55+Parametros!$B$56,Parametros!$C$55+Parametros!$C$56) -> 1936 | D23: =IF(D$4=1,Parametros!$B$55+Parametros!$B$56,Parametros!$C$55+Parametros!$C$56) -> 1936 | E23: =IF(E$4=1,Parametros!$B$55+Parametros!$B$56,Parametros!$C$55+Parametros!$C$56) -> 1936 | F23: =IF(F$4=1,Parametros!$B$55+Parametros!$B$56,Parametros!$C$55+Parametros!$C$56) -> 6402 | G23: =IF(G$4=1,Parametros!$B$55+Parametros!$B$56,Parametros!$C$55+Parametros!$C$56) -> 6402 | H23: =IF(H$4=1,Parametros!$B$55+Parametros!$B$56,Parametros!$C$55+Parametros!$C$56) -> 6402 | I23: =IF(I$4=1,Parametros!$B$55+Parametros!$B$56,Parametros!$C$55+Parametros!$C$56) -> 6402 | J23: =IF(J$4=1,Parametros!$B$55+Parametros!$B$56,Parametros!$C$55+Parametros!$C$56) -> 6402 | ... N23: =IF(N$4=1,Parametros!$B$55+Parametros!$B$56,Parametros!$C$55+Parametros!$C$56) -> 6402
A24: EBITDA ($) | C24: =C22-C23 -> -1723.1004 | D24: =D22-D23 -> -1691.1655 | E24: =E22-E23 -> -1654.4403 | F24: =F22-F23 -> -6078.2064 | G24: =G22-G23 -> -6029.6373 | H24: =H22-H23 -> -5973.7829 | I24: =I22-I23 -> -5909.5503 | J24: =J22-J23 -> -5835.6829 | ... N24: =N22-N23 -> -5411.5078
A25: EBITDA acumulado ($) | C25: =C24 -> -1723.1004 | D25: =C25+D24 -> -3414.2659 | E25: =D25+E24 -> -5068.7062 | F25: =E25+F24 -> -11146.913 | G25: =F25+G24 -> -17176.55 | H25: =G25+H24 -> -23150.333 | I25: =H25+I24 -> -29059.883 | J25: =I25+J24 -> -34895.566 | K25: =J25+K24 -> -40646.301 | ... N25: =M25+N24 -> -57251.557
A26: Take rate efectivo (ingreso / GMV) | C26: =IF(C18=0,0,C19/C18) -> 0.093456043 | D26: =IF(D18=0,0,D19/D18) -> 0.093456043 | E26: =IF(E18=0,0,E19/E18) -> 0.093456043 | F26: =IF(F18=0,0,F19/F18) -> 0.093456043 | G26: =IF(G18=0,0,G19/G18) -> 0.093456043 | H26: =IF(H18=0,0,H19/H18) -> 0.093456043 | I26: =IF(I18=0,0,I19/I18) -> 0.093456043 | J26: =IF(J18=0,0,J19/J18) -> 0.093456043 | ... N26: =IF(N18=0,0,N19/N18) -> 0.093456043
A27: Margen de contribución (contribución / GMV) | C27: =IF(C18=0,0,C22/C18) -> 0.043300875 | D27: =IF(D18=0,0,D22/D18) -> 0.043300875 | E27: =IF(E18=0,0,E22/E18) -> 0.043300875 | F27: =IF(F18=0,0,F22/F18) -> 0.043300875 | G27: =IF(G18=0,0,G22/G18) -> 0.043300875 | H27: =IF(H18=0,0,H22/H18) -> 0.043300875 | I27: =IF(I18=0,0,I22/I18) -> 0.043300875 | J27: =IF(J18=0,0,J22/J18) -> 0.043300875 | ... N27: =IF(N18=0,0,N22/N18) -> 0.043300875
A28: Transacciones necesarias para cubrir los fijos (break-even) | C28: =IF(C22<=0,0,C23/(C22/C$15)) -> 1800.5109 | D28: =IF(D22<=0,0,D23/(D22/D$15)) -> 1800.5109 | E28: =IF(E22<=0,0,E23/(E22/E$15)) -> 1800.5109 | F28: =IF(F22<=0,0,F23/(F22/F$15)) -> 5953.9621 | G28: =IF(G22<=0,0,G23/(G22/G$15)) -> 5953.9621 | H28: =IF(H22<=0,0,H23/(H22/H$15)) -> 5953.9621 | I28: =IF(I22<=0,0,I23/(I22/I$15)) -> 5953.9621 | J28: =IF(J22<=0,0,J23/(J22/J$15)) -> 5953.9621 | ... N28: =IF(N22<=0,0,N23/(N22/N$15)) -> 5953.9621
A31: ESCENARIO PROPUESTA — comisión por vertical, mínimo por transacción, tarifa de servicio
A32: GMV — total pagado por las familias ($) | C32: =SUMPRODUCT(C$6:C$14,UE_Propuesta!$J$5:$J$13) -> 5112.77 | D32: =SUMPRODUCT(D$6:D$14,UE_Propuesta!$J$5:$J$13) -> 5879.6855 | E32: =SUMPRODUCT(E$6:E$14,UE_Propuesta!$J$5:$J$13) -> 6761.6383 | F32: =SUMPRODUCT(F$6:F$14,UE_Propuesta!$J$5:$J$13) -> 7775.8841 | G32: =SUMPRODUCT(G$6:G$14,UE_Propuesta!$J$5:$J$13) -> 8942.2667 | H32: =SUMPRODUCT(H$6:H$14,UE_Propuesta!$J$5:$J$13) -> 10283.607 | I32: =SUMPRODUCT(I$6:I$14,UE_Propuesta!$J$5:$J$13) -> 11826.148 | J32: =SUMPRODUCT(J$6:J$14,UE_Propuesta!$J$5:$J$13) -> 13600.07 | ... N32: =SUMPRODUCT(N$6:N$14,UE_Propuesta!$J$5:$J$13) -> 23786.607
A33: Ingreso de Satori (comisiones + tarifa de servicio, base) ($) | C33: =SUMPRODUCT(C$6:C$14,UE_Propuesta!$M$5:$M$13) -> 876.65217 | D33: =SUMPRODUCT(D$6:D$14,UE_Propuesta!$M$5:$M$13) -> 1008.15 | E33: =SUMPRODUCT(E$6:E$14,UE_Propuesta!$M$5:$M$13) -> 1159.3725 | F33: =SUMPRODUCT(F$6:F$14,UE_Propuesta!$M$5:$M$13) -> 1333.2784 | G33: =SUMPRODUCT(G$6:G$14,UE_Propuesta!$M$5:$M$13) -> 1533.2701 | H33: =SUMPRODUCT(H$6:H$14,UE_Propuesta!$M$5:$M$13) -> 1763.2607 | I33: =SUMPRODUCT(I$6:I$14,UE_Propuesta!$M$5:$M$13) -> 2027.7497 | J33: =SUMPRODUCT(J$6:J$14,UE_Propuesta!$M$5:$M$13) -> 2331.9122 | ... N33: =SUMPRODUCT(N$6:N$14,UE_Propuesta!$M$5:$M$13) -> 4078.529
A34: Costo del riel neto de IVA ($) | C34: =SUMPRODUCT(C$6:C$14,UE_Propuesta!$P$5:$P$13) -> 205.75266 | D34: =SUMPRODUCT(D$6:D$14,UE_Propuesta!$P$5:$P$13) -> 236.61556 | E34: =SUMPRODUCT(E$6:E$14,UE_Propuesta!$P$5:$P$13) -> 272.10789 | F34: =SUMPRODUCT(F$6:F$14,UE_Propuesta!$P$5:$P$13) -> 312.92407 | G34: =SUMPRODUCT(G$6:G$14,UE_Propuesta!$P$5:$P$13) -> 359.86268 | H34: =SUMPRODUCT(H$6:H$14,UE_Propuesta!$P$5:$P$13) -> 413.84209 | I34: =SUMPRODUCT(I$6:I$14,UE_Propuesta!$P$5:$P$13) -> 475.9184 | J34: =SUMPRODUCT(J$6:J$14,UE_Propuesta!$P$5:$P$13) -> 547.30616 | ... N34: =SUMPRODUCT(N$6:N$14,UE_Propuesta!$P$5:$P$13) -> 957.2419
A35: Costos variables ($) | C35: =SUMPRODUCT(C$6:C$14,UE_Propuesta!$Q$5:$Q$13) -> 49.32385 | D35: =SUMPRODUCT(D$6:D$14,UE_Propuesta!$Q$5:$Q$13) -> 56.722428 | E35: =SUMPRODUCT(E$6:E$14,UE_Propuesta!$Q$5:$Q$13) -> 65.230792 | F35: =SUMPRODUCT(F$6:F$14,UE_Propuesta!$Q$5:$Q$13) -> 75.01541 | G35: =SUMPRODUCT(G$6:G$14,UE_Propuesta!$Q$5:$Q$13) -> 86.267722 | H35: =SUMPRODUCT(H$6:H$14,UE_Propuesta!$Q$5:$Q$13) -> 99.20788 | I35: =SUMPRODUCT(I$6:I$14,UE_Propuesta!$Q$5:$Q$13) -> 114.08906 | J35: =SUMPRODUCT(J$6:J$14,UE_Propuesta!$Q$5:$Q$13) -> 131.20242 | ... N35: =SUMPRODUCT(N$6:N$14,UE_Propuesta!$Q$5:$Q$13) -> 229.47386
A36: CONTRIBUCIÓN transaccional + suscripciones ($) | C36: =C33-C34-C35+C$46 -> 621.57567 | D36: =D33-D34-D35+D$46 -> 714.81202 | E36: =E33-E34-E35+E$46 -> 822.03382 | F36: =F33-F34-F35+F$46 -> 945.33889 | G36: =G33-G34-G35+G$46 -> 1087.1397 | H36: =H33-H34-H35+H$46 -> 1250.2107 | I36: =I33-I34-I35+I$46 -> 1437.7423 | J36: =J33-J34-J35+J$46 -> 1653.4036 | ... N36: =N33-N34-N35+N$46 -> 2891.8133
A37: Costos fijos del escenario ($) | C37: =IF(C$4=1,Parametros!$B$55+Parametros!$B$56,Parametros!$C$55+Parametros!$C$56) -> 1936 | D37: =IF(D$4=1,Parametros!$B$55+Parametros!$B$56,Parametros!$C$55+Parametros!$C$56) -> 1936 | E37: =IF(E$4=1,Parametros!$B$55+Parametros!$B$56,Parametros!$C$55+Parametros!$C$56) -> 1936 | F37: =IF(F$4=1,Parametros!$B$55+Parametros!$B$56,Parametros!$C$55+Parametros!$C$56) -> 6402 | G37: =IF(G$4=1,Parametros!$B$55+Parametros!$B$56,Parametros!$C$55+Parametros!$C$56) -> 6402 | H37: =IF(H$4=1,Parametros!$B$55+Parametros!$B$56,Parametros!$C$55+Parametros!$C$56) -> 6402 | I37: =IF(I$4=1,Parametros!$B$55+Parametros!$B$56,Parametros!$C$55+Parametros!$C$56) -> 6402 | J37: =IF(J$4=1,Parametros!$B$55+Parametros!$B$56,Parametros!$C$55+Parametros!$C$56) -> 6402 | ... N37: =IF(N$4=1,Parametros!$B$55+Parametros!$B$56,Parametros!$C$55+Parametros!$C$56) -> 6402
A38: EBITDA ($) | C38: =C36-C37 -> -1314.4243 | D38: =D36-D37 -> -1221.188 | E38: =E36-E37 -> -1113.9662 | F38: =F36-F37 -> -5456.6611 | G38: =G36-G37 -> -5314.8603 | H38: =H36-H37 -> -5151.7893 | I38: =I36-I37 -> -4964.2577 | J38: =J36-J37 -> -4748.5964 | ... N38: =N36-N37 -> -3510.1867
A39: EBITDA acumulado ($) | C39: =C38 -> -1314.4243 | D39: =C39+D38 -> -2535.6123 | E39: =D39+E38 -> -3649.5785 | F39: =E39+F38 -> -9106.2396 | G39: =F39+G38 -> -14421.1 | H39: =G39+H38 -> -19572.889 | I39: =H39+I38 -> -24537.147 | J39: =I39+J38 -> -29285.743 | K39: =J39+K38 -> -33786.329 | ... N39: =M39+N38 -> -45399.269
A40: Take rate efectivo (ingreso / GMV) | C40: =IF(C32=0,0,C33/C32) -> 0.17146325 | D40: =IF(D32=0,0,D33/D32) -> 0.17146325 | E40: =IF(E32=0,0,E33/E32) -> 0.17146325 | F40: =IF(F32=0,0,F33/F32) -> 0.17146325 | G40: =IF(G32=0,0,G33/G32) -> 0.17146325 | H40: =IF(H32=0,0,H33/H32) -> 0.17146325 | I40: =IF(I32=0,0,I33/I32) -> 0.17146325 | J40: =IF(J32=0,0,J33/J32) -> 0.17146325 | ... N40: =IF(N32=0,0,N33/N32) -> 0.17146325
A41: Margen de contribución (contribución / GMV) | C41: =IF(C32=0,0,C36/C32) -> 0.12157317 | D41: =IF(D32=0,0,D36/D32) -> 0.12157317 | E41: =IF(E32=0,0,E36/E32) -> 0.12157317 | F41: =IF(F32=0,0,F36/F32) -> 0.12157317 | G41: =IF(G32=0,0,G36/G32) -> 0.12157317 | H41: =IF(H32=0,0,H36/H32) -> 0.12157317 | I41: =IF(I32=0,0,I36/I32) -> 0.12157317 | J41: =IF(J32=0,0,J36/J32) -> 0.12157317 | ... N41: =IF(N32=0,0,N36/N32) -> 0.12157317
A42: Transacciones necesarias para cubrir los fijos (break-even) | C42: =IF(C36<=0,0,C37/(C36/C$15)) -> 616.70368 | D42: =IF(D36<=0,0,D37/(D36/D$15)) -> 616.70368 | E42: =IF(E36<=0,0,E37/(E36/E$15)) -> 616.70368 | F42: =IF(F36<=0,0,F37/(F36/F$15)) -> 2039.3269 | G42: =IF(G36<=0,0,G37/(G36/G$15)) -> 2039.3269 | H42: =IF(H36<=0,0,H37/(H36/H$15)) -> 2039.3269 | I42: =IF(I36<=0,0,I37/(I36/I$15)) -> 2039.3269 | J42: =IF(J36<=0,0,J37/(J36/J$15)) -> 2039.3269 | ... N42: =IF(N36<=0,0,N37/(N36/N$15)) -> 2039.3269
A43: Ingresos NO transaccionales (base sin IVA) — solo en fase Operación
...

Sheet Caja_retenciones
A1: CAJA — lo que las tarjetas retienen y cuánto queda atrapado (escenario PROPUESTA)
A2: Las retenciones no son costo: son crédito contra impuestos. Pero salen de la caja el día del cobro y vuelven meses después. El exceso de IVA retenido es recuperable por devolución cuando no se compensa en 6 meses (Art. 69 LRTI) — acá se modela recuperación a los 7 meses.
A4: Concepto | B4: oct-26 | C4: nov-26 | D4: dic-26 | E4: ene-27 | F4: feb-27 | G4: mar-27 | H4: abr-27 | I4: may-27 | J4: jun-27 | K4: jul-27 | L4: ago-27 | M4: sep-27
A5: Retención renta 2 % (crédito contra renta) ($) | C5: =SUMPRODUCT(PyL_mensual!C$6:C$14,UE_Propuesta!$U$5:$U$13) -> 45.569426 | D5: =SUMPRODUCT(PyL_mensual!D$6:D$14,UE_Propuesta!$U$5:$U$13) -> 52.40484 | E5: =SUMPRODUCT(PyL_mensual!E$6:E$14,UE_Propuesta!$U$5:$U$13) -> 60.265566 | F5: =SUMPRODUCT(PyL_mensual!F$6:F$14,UE_Propuesta!$U$5:$U$13) -> 69.305401 | G5: =SUMPRODUCT(PyL_mensual!G$6:G$14,UE_Propuesta!$U$5:$U$13) -> 79.701211 | H5: =SUMPRODUCT(PyL_mensual!H$6:H$14,UE_Propuesta!$U$5:$U$13) -> 91.656393 | I5: =SUMPRODUCT(PyL_mensual!I$6:I$14,UE_Propuesta!$U$5:$U$13) -> 105.40485 | J5: =SUMPRODUCT(PyL_mensual!J$6:J$14,UE_Propuesta!$U$5:$U$13) -> 121.21558 | ... N5: =SUMPRODUCT(PyL_mensual!N$6:N$14,UE_Propuesta!$U$5:$U$13) -> 212.00681
A6: Retención IVA por tarjetas ($) | C6: =SUMPRODUCT(PyL_mensual!C$6:C$14,UE_Propuesta!$V$5:$V$13) -> 128.59349 | D6: =SUMPRODUCT(PyL_mensual!D$6:D$14,UE_Propuesta!$V$5:$V$13) -> 147.88251 | E6: =SUMPRODUCT(PyL_mensual!E$6:E$14,UE_Propuesta!$V$5:$V$13) -> 170.06489 | F6: =SUMPRODUCT(PyL_mensual!F$6:F$14,UE_Propuesta!$V$5:$V$13) -> 195.57462 | G6: =SUMPRODUCT(PyL_mensual!G$6:G$14,UE_Propuesta!$V$5:$V$13) -> 224.91081 | H6: =SUMPRODUCT(PyL_mensual!H$6:H$14,UE_Propuesta!$V$5:$V$13) -> 258.64743 | I6: =SUMPRODUCT(PyL_mensual!I$6:I$14,UE_Propuesta!$V$5:$V$13) -> 297.44455 | J6: =SUMPRODUCT(PyL_mensual!J$6:J$14,UE_Propuesta!$V$5:$V$13) -> 342.06123 | ... N6: =SUMPRODUCT(PyL_mensual!N$6:N$14,UE_Propuesta!$V$5:$V$13) -> 598.26723
A7: IVA por pagar de Satori antes de retenciones ($) | C7: =SUMPRODUCT(PyL_mensual!C$6:C$14,UE_Propuesta!$W$5:$W$13) -> 188.73951 | D7: =SUMPRODUCT(PyL_mensual!D$6:D$14,UE_Propuesta!$W$5:$W$13) -> 217.05044 | E7: =SUMPRODUCT(PyL_mensual!E$6:E$14,UE_Propuesta!$W$5:$W$13) -> 249.60801 | F7: =SUMPRODUCT(PyL_mensual!F$6:F$14,UE_Propuesta!$W$5:$W$13) -> 287.04921 | G7: =SUMPRODUCT(PyL_mensual!G$6:G$14,UE_Propuesta!$W$5:$W$13) -> 330.10659 | H7: =SUMPRODUCT(PyL_mensual!H$6:H$14,UE_Propuesta!$W$5:$W$13) -> 379.62258 | I7: =SUMPRODUCT(PyL_mensual!I$6:I$14,UE_Propuesta!$W$5:$W$13) -> 436.56596 | J7: =SUMPRODUCT(PyL_mensual!J$6:J$14,UE_Propuesta!$W$5:$W$13) -> 502.05086 | ... N7: =SUMPRODUCT(PyL_mensual!N$6:N$14,UE_Propuesta!$W$5:$W$13) -> 878.09009
A8: Exceso de IVA retenido en el mes ($) | C8: =MAX(C6-MAX(C7,0),0) -> 0 | D8: =MAX(D6-MAX(D7,0),0) -> 0 | E8: =MAX(E6-MAX(E7,0),0) -> 0 | F8: =MAX(F6-MAX(F7,0),0) -> 0 | G8: =MAX(G6-MAX(G7,0),0) -> 0 | H8: =MAX(H6-MAX(H7,0),0) -> 0 | I8: =MAX(I6-MAX(I7,0),0) -> 0 | J8: =MAX(J6-MAX(J7,0),0) -> 0 | ... N8: =MAX(N6-MAX(N7,0),0) -> 0
A9: IVA que Satori paga en efectivo en el mes ($) | C9: =MAX(C7-C6,0) -> 60.146027 | D9: =MAX(D7-D6,0) -> 69.167931 | E9: =MAX(E7-E6,0) -> 79.543121 | F9: =MAX(F7-F6,0) -> 91.474589 | G9: =MAX(G7-G6,0) -> 105.19578 | H9: =MAX(H7-H6,0) -> 120.97514 | I9: =MAX(I7-I6,0) -> 139.12142 | J9: =MAX(J7-J6,0) -> 159.98963 | ... N9: =MAX(N7-N6,0) -> 279.82286
A10: Exceso IVA acumulado ($) | C10: =C8 -> 0 | D10: =C10+D8 -> 0 | E10: =D10+E8 -> 0 | F10: =E10+F8 -> 0 | G10: =F10+G8 -> 0 | H10: =G10+H8 -> 0 | I10: =H10+I8 -> 0 | J10: =I10+J8 -> 0 | K10: =J10+K8 -> 0 | ... N10: =M10+N8 -> 0
A11: Recuperación por devolución (exceso de hace 7 meses) ($) | C11: =0 -> 0 | D11: =0 -> 0 | E11: =0 -> 0 | F11: =0 -> 0 | G11: =0 -> 0 | H11: =0 -> 0 | I11: =0 -> 0 | J11: =C8 -> 0 | K11: =D8 -> 0 | L11: =E8 -> 0 | M11: =F8 -> 0 | N11: =G8 -> 0
A12: IVA atrapado neto ($) | C12: =C10-SUM($C$11:C11) -> 0 | D12: =D10-SUM($C$11:D11) -> 0 | E12: =E10-SUM($C$11:E11) -> 0 | F12: =F10-SUM($C$11:F11) -> 0 | G12: =G10-SUM($C$11:G11) -> 0 | H12: =H10-SUM($C$11:H11) -> 0 | I12: =I10-SUM($C$11:I11) -> 0 | J12: =J10-SUM($C$11:J11) -> 0 | ... N12: =N10-SUM($C$11:N11) -> 0
A13: Renta retenida acumulada — crédito contra el ejercicio; con pérdida, saldo a reclamar ($) | C13: =C5 -> 45.569426 | D13: =C13+D5 -> 97.974266 | E13: =D13+E5 -> 158.23983 | F13: =E13+F5 -> 227.54523 | G13: =F13+G5 -> 307.24644 | H13: =G13+H5 -> 398.90284 | I13: =H13+I5 -> 504.30769 | J13: =I13+J5 -> 625.52327 | K13: =J13+K5 -> 764.92118 | ... N13: =M13+N5 -> 1321.5893
A14: CAJA ATRAPADA TOTAL ($) | C14: =C12+C13 -> 45.569426 | D14: =D12+D13 -> 97.974266 | E14: =E12+E13 -> 158.23983 | F14: =F12+F13 -> 227.54523 | G14: =G12+G13 -> 307.24644 | H14: =H12+H13 -> 398.90284 | I14: =I12+I13 -> 504.30769 | J14: =J12+J13 -> 625.52327 | ... N14: =N12+N13 -> 1321.5893
